Workbook

Sheet AS2 Overview
A1: Session 6 case workbook — three AS2 deliverables
A2: For each deliverable: retain Session 5 analysis, add Session 6 concepts, emulate the completed view and explain the readings.
A4: AS2 Deliverable | B4: Session 5: carry forward | C4: Session 6: expected addition | D4: Completed example / screenshot | E4: Readings to explain | F4: Case paragraph IDs
A5: 1. Business alignment and SHRBP mandate | B5: Business priority, organizational arrangement, responsibilities, decision rights and coordination constraints. | C5: Translate arrangements into role purposes, reporting, accountable owners, bounded authority and escalation. | D5: D1 HR Alignment: completed output-to-role ownership table and screenshot, followed by your own table. | E5: Read 1 Mintzberg; Read 2 Dessler strategic HRM/workforce planning. | F5: P008–P014; P019–P021; P042–P044
A6: 2. Work design and workforce plan | B6: Workload, productive capacity, retained service obligations, demand–supply gaps and options. | C6: Explain job analysis, JD versus JS and rotation/enlargement/enrichment. Link three role designs to calculations. | D6: D2 Work and Roles: live role calculation example, JD/JS examples and screenshot; complete three role designs. | E6: Read 2 Dessler strategic HRM/workforce planning; Read 3 job analysis/design set. | F6: P023–P029; P050–P052; P063; P069–P071; P168; P183–P184; Q5.01–Q5.08
A7: 3. Attraction, selection and onboarding | B7: Capability gaps, internal availability, release constraints, vendor cost and hiring timing. | C7: Convert gaps into sourcing, relevant selection evidence, onboarding and ready-to-work checks. | D7: D3 Staffing Readiness: completed gap-to-readiness example and screenshot, followed by your own table. | E7: Read 3 job analysis/design set; revisit Read 2 for timing and costs. | F7: P027; P061–P064; P069–P071; P187–P190; P207–P208; Q5.07–Q5.08; Q6.01–Q6.07
A9: All-encompassing AS2 requirement | B9: Constitute an HR function whose mandate, roles, workforce calculations and staffing readiness support the same business alignment.
A10: Five-step route | B10: 1 Diagnose output/authority; 2 calculate demand/supply; 3 allocate and test constraints; 4 produce roles/staffing readiness; 5 challenge and defend.
A11: Assessment readiness | B11: If attendance dips, faculty may execute preparatory AS2 /15. Otherwise use the analytical lab route. Final /10 on 19 October 2026; full /25 only if preparatory assessment not exercised.
A12: Evidence | B12: Three core slides, one per deliverable, plus e-portfolio/app and mentor/accountability slides. Bring live Excel and named contribution evidence.
A13: Assumptions | B13: Q5 is issued teaching input; Q6 and completed role/staffing examples are labelled proposals. Make justified assumptions where missing and record sources, owner and downside.

Sheet D1 HR Alignment
A1: Deliverable 1 — Business alignment and SHRBP mandate
A2: Illustrative completed view: emulate the method and justify your own decisions. Proposed owners/criteria/timing are assumptions, not approvals.
A3: Session 5 carry forward | B3: Organizational arrangement, work ownership and decision boundaries.
A4: Session 6 expected | B4: Role purpose, reporting, responsibility and bounded decision rights.
A5: Explain in class | B5: Explain why a reporting line or new HR department does not automatically authorize a product decision.
A6: Readings / case IDs | B6: Read 1 Mintzberg; Read 2 Dessler. P008–P014; P042–P044; P027.
A8: Business output / source | B8: Work / role | C8: Accountable owner | D8: Role authority / reporting | E8: Escalation / approval | F8: SHRBP contribution
A9: Pilot delivered while existing services continue; P008–P010 | B9: Delivery coordination; Kabir / delivery role | C9: Propose Kabir for pilot coordination; Rao for cross-functional resolution | D9: Coordinate agreed work; no assumed power over pricing, consent or major architecture exceptions | E9: Name authorized technical/commercial owners; propose a response clock subject to acceptance | F9: Translate mandate into duties, workload, reporting and people responsibilities.
A10: One authoritative customer-data output; P024; Q5.04 | B10: Customer-data preparation specialist | C10: Student proposal: operating owner plus named product/regional receiver | D10: Prepare and validate shared output; internal release must be authorized | E10: Receiving owners must accept common output before duplicate is excluded | F10: Define JD/JS and confirm work ownership and capacity consequences.
A11: Legacy continuity and knowledge transfer; P027; P069–P071 | B11: Legacy expert and source-service cover | C11: Student proposal: source-service manager for release; delivery owner for pilot schedule | D11: Release within available hours; protect service commitments | E11: No transfer without cover; escalation owner/time must be proposed and verified | F11: Test deployability, competency evidence and protected learning arrangements.
A13: Your group response — complete this table before Session 6
A14: Business output / source | B14: Work / role | C14: Accountable owner | D14: Role authority / reporting | E14: Escalation / approval | F14: SHRBP contribution
A15: Routine technical readiness within agreed thresholds; P019–P020 | B15: Technical lead / qualified local engineering role | C15: Named technical lead; reports through pilot delivery structure | D15: Escalate threshold breach or combined-impact change to architecture council; proposed response clock needs approval | E15: Define role boundaries, competency evidence and escalation process; do not confer commercial or customer-use authority
A16: Commercial approval and customer permission; P008–P010, P019–P020 | B16: Commercial/data-access reviewer and relevant product team | C16: Existing global/regional commercial and data-access owners | D16: Pricing, customer consent/access and permission for customer use remain with existing authorized owners | E16: Align staffing and onboarding to the separate technical, commercial and customer-permission clocks
A17: Existing service continuity and legacy knowledge; P027, P069–P071, P168, P183–P184 | B17: Source-service manager + legacy expert + delivery manager | C17: Source-service manager approves release; delivery manager sequences protected teaching | D17: Escalate if service cover or protected teaching time is unavailable; no release by assumption | E17: Check deployable capacity, protected transfer time and readiness evidence before committing people
A19: Aspirational screenshot of the completed example is embedded below.

Sheet D2 Work and Roles
A1: Deliverable 2 — Work design and workforce plan
A2: Illustrative completed view: emulate the method and justify your own decisions. Proposed owners/criteria/timing are assumptions, not approvals.
A3: Session 5 carry forward | B3: Demand/supply calculations, skills, timing and protected service hours.
A4: Session 6 expected | B4: Job analysis and three JD/JS designs linked to calculated work. Explain task/authority changes.
A5: Explain in class | B5: Distinguish task demand, FTE, available headcount and approved allocation; explain positive role gaps.
A6: Readings / case IDs | B6: Read 2 + Read 3. P023–P029; P050–P052; P063; P069–P071; P168; P183–P184.
A8: Role / source | B8: Pilot demand h | C8: Potential supply h | D8: Skill gap h | E8: Vendor count | F8: Vendor cost INR
A9: Data preparation; bounded/single output; Q5.03–Q5.08 | B9: ='Four scenarios'!E27 | C9: ='Four scenarios'!F27 | D9: ='Four scenarios'!H27 | E9: ='Four scenarios'!I27 | F9: ='Four scenarios'!J27
A10: Quality assurance; bounded/single output; Q5.03–Q5.08 | B10: ='Four scenarios'!E28 | C10: ='Four scenarios'!F28 | D10: ='Four scenarios'!H28 | E10: ='Four scenarios'!I28 | F10: ='Four scenarios'!J28
A11: Legacy experts; bounded/single output; Q5.03–Q5.08 | B11: ='Four scenarios'!E29 | C11: ='Four scenarios'!F29 | D11: ='Four scenarios'!H29 | E11: ='Four scenarios'!I29 | F11: ='Four scenarios'!J29
A13: Your group response — complete this table before Session 6
A14: Role / source | B14: Pilot demand h | C14: Potential supply h | D14: Skill gap h | E14: Vendor count | F14: Vendor cost INR
A15: Data preparation; bounded/single output; Q5.03–Q5.08 | B15: ='Four scenarios'!E27 | C15: ='Four scenarios'!F27 | D15: ='Four scenarios'!H27 | E15: ='Four scenarios'!I27 | F15: ='Four scenarios'!J27
A16: Quality assurance; bounded/single output; Q5.03–Q5.08 | B16: ='Four scenarios'!E28 | C16: ='Four scenarios'!F28 | D16: ='Four scenarios'!H28 | E16: ='Four scenarios'!I28 | F16: ='Four scenarios'!J28
A17: Legacy experts; bounded/single output; Q5.03–Q5.08 | B17: ='Four scenarios'!E29 | C17: ='Four scenarios'!F29 | D17: ='Four scenarios'!H29 | E17: ='Four scenarios'!I29 | F17: ='Four scenarios'!J29
A19: Aspirational screenshot of the completed example is embedded below.
A21: Three illustrative JD/JS designs — complete and justify your own alternatives
A22: Role | B22: JD: duties/output | C22: JD: authority/reporting | D22: JS: competencies | E22: Design intervention | F22: Readiness/selection evidence
A23: Data preparation | B23: Prepare 60 shared packs and validate exceptions; role-pool workload, not one employee task list. | C23: Proposed preparation owner; preserve customer-access approval. | D23: Reconciliation, exception judgement, documentation. | E23: Remove duplicate output only with receiving-owner agreement. | F23: Standardized anomalous-record work sample; protected shadowing. P024; P069.
A24: Quality assurance | B24: 80 validation tasks; 240 task hours plus selected coordination. | C24: Proposed validation owner; technical acceptance/escalation remains named. | D24: Test execution, evidence interpretation, risk escalation. | E24: Enrichment only if discretion and support are granted; no automatic authority transfer. | F24: Same validation work sample/rubric for candidates; record acceptance gate. Q5.04; P019.
A25: Legacy expert | B25: 40 teaching/documentation blocks;160 task hours plus coordination. | C25: Source-service manager authorizes release; pilot owner protects transfer time. | D25: Contract exceptions, teaching, knowledge documentation. | E25: Protected rotation/practice with service cover; not two full workloads. | F25: Demonstrate exception transfer and learner competence. P063; P069–P071; P168.

Sheet D3 Staffing Readiness
A1: Deliverable 3 — Attraction, selection and onboarding
A2: Illustrative completed view: emulate the method and justify your own decisions. Proposed owners/criteria/timing are assumptions, not approvals.
A3: Session 5 carry forward | B3: Skill gap, internal release constraint, vendor cost and eight-week permanent-hire lead.
A4: Session 6 expected | B4: Gap-to-source choice, evidence-based selection and explicit onboarding/readiness checks.
A5: Explain in class | B5: Explain why selecting a worker is not the same as access, authority or productive readiness.
A6: Readings / case IDs | B6: Read 3; revisit Read 2. P061–P064; P069–P071; P187–P190; P207–P208.
A8: Gap / source | B8: Sourcing option | C8: Selection evidence | D8: Onboarding / readiness gate | E8: Owner and timing | F8: Cost and condition
A9: Data preparation gap 80h in bounded/single-output full-release illustration; Q5.03–Q5.08 | B9: One role-specific vendor worker if internal release and redesign conditions hold. | C9: Proposed common work sample: reconcile anomalous customer pack; validate ability, not title alone. | D9: Customer-data access authorized; internal expert introduces exceptions; tested shared-output handoff. | E9: Procurement for supplier, operating owner for access; baseline start week1; approval required. | F9: ₹88,000 (1×160×₹550); extra induction cost/time must be estimated separately if not already covered.
A10: QA gap72h; Q5.03–Q5.08 | B10: One QA vendor under baseline effective capacity102.4h. | C10: Proposed standardized validation task and judgement questions. | D10: Understand acceptance/escalation threshold; observe supervised validation; demonstrate readiness. | E10: QA/technical owner; start assumption week1 subject to access and induction. | F10: ₹128,000 (1×160×₹800); no claim that vendor owns technical authorization.
A11: Legacy-expert gap64h; P027; P069–P071; Q5.03–Q5.08 | B11: One specialist vendor is a numerical option; assess tacit-knowledge fit and internal transfer dependency. | C11: Proposed contract-exception explanation plus documentation/teaching demonstration. | D11: Internal knowledge owner verifies interpretation; protected transfer and service cover required. | E11: Source-service owner plus delivery owner; verify knowledge-access timing. | F11: ₹160,000 (1×160×₹1,000); vendor skill does not automatically replace internal context.
A13: Your group response — complete this table before Session 6
A14: Gap / source | B14: Sourcing option | C14: Selection evidence | D14: Onboarding / readiness gate | E14: Owner and timing | F14: Cost and condition
A15: Data preparation gap 80h; Q5.03–Q5.08; P024 | B15: One role-specific vendor worker, conditional on one accepted output and authorized release | C15: Standardized customer-pack reconciliation work sample; same rubric for all candidates | D15: Authorize data access; supervised exception practice; receiver signs off shared output | E15: Procurement + operating owner; Week 1 start is an assumption, subject to approval | F15: ₹88,000 = 1 × 160 paid h × ₹550; extra onboarding cost excluded unless separately estimated
A16: QA gap 72h; Q5.03–Q5.08; P019–P020 | B16: One QA vendor, conditional on acceptance criteria and system access | C16: Validation work sample + exception judgement + documented defect log | D16: Train on acceptance thresholds; supervised validation; technical owner confirms readiness | E16: QA/technical owner + procurement; Week 1 start is an assumption | F16: ₹1,28,000 = 1 × 160 paid h × ₹800; vendor does not gain approval authority
A17: Legacy-expert gap 64h; Q5.03–Q5.08; P027, P069–P071, P168 | B17: One specialist vendor is a numerical option; compare with protected internal knowledge transfer | C17: Explain an exception, document it and teach a second person to apply it | D17: Named internal expert verifies learning; source-service cover and protected transfer time required | E17: Source-service manager + delivery manager; date must be verified | F17: ₹1,60,000 = 1 × 160 paid h × ₹1,000; vendor cost does not eliminate internal-context dependency
A19: Aspirational screenshot of the completed example is embedded below.

Sheet Three Readings
A1: Session 6 — three reading sets students must explain
A2: Reading | B2: Assigned portion | C2: Concept explanation | D2: Apply to deliverable | E2: Case IDs / task
A3: 1 Mintzberg (1980), R1 | B3: Assigned abstract paras1–9 and supplied native figures: parts, configurations and decentralization. | C3: How work is coordinated and authority distributed; distinguish reporting from final decision rights. | D3: D1; supports D2 ownership. | E3: P008–P014; P042–P044. Explain one decision boundary in D1.
A4: 2 Dessler (2020), R2 | B4: Chapter3 pp90–91 and Chapter5 pp144–145; prescribed book/institutional access. | C4: Strategic HR alignment; workforce demand, deployable supply, gaps and response timing. | D4: D1 business fit; D2 numerical plan; D3 timing. | E4: P023–P029; P050–P052; Q5.01–Q5.08. Explain one demand/supply formula.
A5: 3 Job analysis/design, R3 | B5: Dessler Chapter4 pp113–115 plus CIPD Job design first two public introductory paragraphs. | C5: Job analysis; JD/JS; connect job design to workload and staffing. Explain rotation, enlargement and enrichment with appropriate supporting textbook reading. | D5: D2 roles; D3 competencies, selection and onboarding. | E5: P061–P064; P069–P071; P168; P183–P184. Explain one proposed role change.
A7: CIPD public reading | B7: https://www.cipd.org/en/knowledge/factsheets/job-design-factsheet/
A8: Student viva | B8: For each reading: explain concept → cite P/Q evidence → show calculation or role change → defend choice.
A9: Textbook access | B9: Use prescribed copies/institutional access. These tables guide application and do not reproduce textbook pages.

Sheet Inputs
A2: Inputs — Q5 case records and Q6 scenario assumptions
A5: Parameter | B5: Value | C5: Unit | D5: Source / meaning
A6: Window | B6: 4 | C6: weeks | D6: Q5.01
A7: Weekly hours | B7: 40 | C7: paid hours | D7: Q5.02
A8: Allowance | B8: 0.2 | C8: share | D8: Q5.02
A9: Vendor proficiency | B9: 0.8 | C9: effective share | D9: Q5.07; change only as labelled scenario
A10: Vendor budget | B10: 600000 | C10: INR | D10: Q5.07
A11: Vendor limit | B11: 8 | C11: people | D11: Q5.07
A12: Permanent-hire lead | B12: 8 | C12: weeks | D12: Q5.07
A13: Workflow | B13: 1 | C13: 1 retained / 2 bounded | D13: Q5.05; conditional authority
A14: Include duplicate | B14: 1 | C14: 1 yes / 0 no | D14: Q5.04; exclusion requires common-output owner
A15: Vendor delay | B15: 0 | C15: weeks | D15: Q6.03 optional downside assumption; baseline zero
A16: Extra role workload | B16: 0 | C16: hours per role | D16: Q6.02; specialist/onboarding additions beyond Q5
A17: Extra incremental cost | B17: 0 | C17: INR | D17: Q6.04; justify zero or record assumed additional costs
A18: Employee productive hours | B18: =B6*B7*(1-B8) | C18: hours/person | D18: Calculated
A19: Vendor paid hours | B19: =MAX(0,B6-B15)*B7 | C19: hours/worker | D19: Calculated after assumed delay
A20: Vendor effective hours | B20: =B19*(1-B8)*B9 | C20: role-hours/worker | D20: Calculated
A21: Source case | B21: Case 9.7 | C21: P001–P232 | D21: Original narrative retained
A22: Scope | B22: One pilot | C22: four weeks | D22: Do not extrapolate to 8,400 staff or 600 positions
B23: Allocation rule | C23: Release flags start at 0 | D23: Do not treat theoretical capacity as approved deployment; change only with named owner evidence.
B24: Recommended scenario | C24: Workflow 2 + duplicate 0 | D24: Conditional only: bounded authority and single-output receiver acceptance required.
A25: Role | B25: Pool people | C25: Legacy h/person | D25: Volume | E25: Hours/unit | F25: Retained coord h | G25: Bounded coord h | H25: Vendor INR/hour | I25: Source
A26: Engineering | B26: 20 | C26: 96 | D26: 120 | E26: 4 | F26: 160 | G26: 80 | H26: 1000 | I26: Q5.03–Q5.07
A27: Analytics | B27: 12 | C27: 80 | D27: 80 | E27: 4 | F27: 96 | G27: 48 | H27: 900 | I27: Q5.03–Q5.07
A28: Operations | B28: 8 | C28: 96 | D28: 60 | E28: 3 | F28: 64 | G28: 32 | H28: 600 | I28: Q5.03–Q5.07
A29: Data preparation | B29: 6 | C29: 96 | D29: 60 | E29: 4 | F29: 64 | G29: 32 | H29: 550 | I29: Q5.03–Q5.07
A30: Quality assurance | B30: 6 | C30: 96 | D30: 80 | E30: 3 | F30: 48 | G30: 24 | H30: 800 | I30: Q5.03–Q5.07
A31: Legacy experts | B31: 8 | C31: 112 | D31: 40 | E31: 4 | F31: 64 | G31: 32 | H31: 1000 | I31: Q5.03–Q5.07

Sheet Work and gaps
A2: Role calculations — demand, released supply, gap and cost
A5: Role | B5: Task h | C5: Coord h | D5: Extra h | E5: Pilot demand h | F5: Legacy h | G5: Available pilot h | H5: Approved assigned h | I5: Gap vs supply h | J5: Gap vs assignment h | K5: Gross FTE | L5: Whole positions | M5: Vendor workers | N5: Vendor cost INR | O5: Unfilled after vendor h
A6: =Inputs!A26 | B6: =Inputs!D26*Inputs!E26+IF(A6="Data preparation",240*Inputs!$B$14,0) | C6: =IF(Inputs!$B$13=1,Inputs!F26,Inputs!G26) | D6: =Inputs!$B$16 | E6: =SUM(B6:D6) | F6: =Inputs!B26*Inputs!C26 | G6: =Inputs!B26*MAX(0,Inputs!$B$18-Inputs!C26) | H6: =SUMIF('Employee allocations'!$B$6:$B$65,A6,'Employee allocations'!$K$6:$K$65) | I6: =MAX(0,E6-G6) | J6: =MAX(0,E6-H6) | K6: =(F6+E6)/Inputs!$B$18 | L6: =ROUNDUP(K6,0) | M6: =IF(Inputs!$B$20>0,ROUNDUP(J6/Inputs!$B$20,0),0) | N6: =M6*Inputs!$B$19*Inputs!H26 | O6: =MAX(0,J6-M6*Inputs!$B$20)
A7: =Inputs!A27 | B7: =Inputs!D27*Inputs!E27+IF(A7="Data preparation",240*Inputs!$B$14,0) | C7: =IF(Inputs!$B$13=1,Inputs!F27,Inputs!G27) | D7: =Inputs!$B$16 | E7: =SUM(B7:D7) | F7: =Inputs!B27*Inputs!C27 | G7: =Inputs!B27*MAX(0,Inputs!$B$18-Inputs!C27) | H7: =SUMIF('Employee allocations'!$B$6:$B$65,A7,'Employee allocations'!$K$6:$K$65) | I7: =MAX(0,E7-G7) | J7: =MAX(0,E7-H7) | K7: =(F7+E7)/Inputs!$B$18 | L7: =ROUNDUP(K7,0) | M7: =IF(Inputs!$B$20>0,ROUNDUP(J7/Inputs!$B$20,0),0) | N7: =M7*Inputs!$B$19*Inputs!H27 | O7: =MAX(0,J7-M7*Inputs!$B$20)
A8: =Inputs!A28 | B8: =Inputs!D28*Inputs!E28+IF(A8="Data preparation",240*Inputs!$B$14,0) | C8: =IF(Inputs!$B$13=1,Inputs!F28,Inputs!G28) | D8: =Inputs!$B$16 | E8: =SUM(B8:D8) | F8: =Inputs!B28*Inputs!C28 | G8: =Inputs!B28*MAX(0,Inputs!$B$18-Inputs!C28) | H8: =SUMIF('Employee allocations'!$B$6:$B$65,A8,'Employee allocations'!$K$6:$K$65) | I8: =MAX(0,E8-G8) | J8: =MAX(0,E8-H8) | K8: =(F8+E8)/Inputs!$B$18 | L8: =ROUNDUP(K8,0) | M8: =IF(Inputs!$B$20>0,ROUNDUP(J8/Inputs!$B$20,0),0) | N8: =M8*Inputs!$B$19*Inputs!H28 | O8: =MAX(0,J8-M8*Inputs!$B$20)
A9: =Inputs!A29 | B9: =Inputs!D29*Inputs!E29+IF(A9="Data preparation",240*Inputs!$B$14,0) | C9: =IF(Inputs!$B$13=1,Inputs!F29,Inputs!G29) | D9: =Inputs!$B$16 | E9: =SUM(B9:D9) | F9: =Inputs!B29*Inputs!C29 | G9: =Inputs!B29*MAX(0,Inputs!$B$18-Inputs!C29) | H9: =SUMIF('Employee allocations'!$B$6:$B$65,A9,'Employee allocations'!$K$6:$K$65) | I9: =MAX(0,E9-G9) | J9: =MAX(0,E9-H9) | K9: =(F9+E9)/Inputs!$B$18 | L9: =ROUNDUP(K9,0) | M9: =IF(Inputs!$B$20>0,ROUNDUP(J9/Inputs!$B$20,0),0) | N9: =M9*Inputs!$B$19*Inputs!H29 | O9: =MAX(0,J9-M9*Inputs!$B$20)
A10: =Inputs!A30 | B10: =Inputs!D30*Inputs!E30+IF(A10="Data preparation",240*Inputs!$B$14,0) | C10: =IF(Inputs!$B$13=1,Inputs!F30,Inputs!G30) | D10: =Inputs!$B$16 | E10: =SUM(B10:D10) | F10: =Inputs!B30*Inputs!C30 | G10: =Inputs!B30*MAX(0,Inputs!$B$18-Inputs!C30) | H10: =SUMIF('Employee allocations'!$B$6:$B$65,A10,'Employee allocations'!$K$6:$K$65) | I10: =MAX(0,E10-G10) | J10: =MAX(0,E10-H10) | K10: =(F10+E10)/Inputs!$B$18 | L10: =ROUNDUP(K10,0) | M10: =IF(Inputs!$B$20>0,ROUNDUP(J10/Inputs!$B$20,0),0) | N10: =M10*Inputs!$B$19*Inputs!H30 | O10: =MAX(0,J10-M10*Inputs!$B$20)
A11: =Inputs!A31 | B11: =Inputs!D31*Inputs!E31+IF(A11="Data preparation",240*Inputs!$B$14,0) | C11: =IF(Inputs!$B$13=1,Inputs!F31,Inputs!G31) | D11: =Inputs!$B$16 | E11: =SUM(B11:D11) | F11: =Inputs!B31*Inputs!C31 | G11: =Inputs!B31*MAX(0,Inputs!$B$18-Inputs!C31) | H11: =SUMIF('Employee allocations'!$B$6:$B$65,A11,'Employee allocations'!$K$6:$K$65) | I11: =MAX(0,E11-G11) | J11: =MAX(0,E11-H11) | K11: =(F11+E11)/Inputs!$B$18 | L11: =ROUNDUP(K11,0) | M11: =IF(Inputs!$B$20>0,ROUNDUP(J11/Inputs!$B$20,0),0) | N11: =M11*Inputs!$B$19*Inputs!H31 | O11: =MAX(0,J11-M11*Inputs!$B$20)
A13: Total flexible roles | B13: =SUM(B6:B11) | C13: =SUM(C6:C11) | D13: =SUM(D6:D11) | E13: =SUM(E6:E11) | F13: =SUM(F6:F11) | G13: =SUM(G6:G11) | H13: =SUM(H6:H11) | I13: =SUM(I6:I11) | ... O13: =SUM(O6:O11)
A16: Vendor budget balance | B16: =Inputs!B10-N13-Inputs!B17
A17: Vendor people limit | B17: =Inputs!B11-M13
A18: Capacity breach h | B18: =SUM('Employee allocations'!L6:L65)
A19: Unfilled pilot work h | B19: =O13
A20: Governance pilot h | B20: 64
A21: Governance people | B21: 4
A22: Plan status | B22: =IF(B18>0,"Capacity breach",IF(B19>0,"Unfilled work",IF(OR(B16<0,B17<0),"Over budget/limit","Numerically feasible; approvals need verification")))
A23: Shortage interpretation | B23: Gap vs supply assumes release. Gap vs assignment uses approved allocated hours. Sum positive gaps by role.
A24: FTE distinction | B24: Gross FTE includes retained+pilot work; whole positions round separately by role. These are not new recruits.

Sheet Employee allocations
A2: Named employee allocation — preserve legacy service commitments
A5: Employee ID | B5: Role | C5: Legacy h | D5: Productive h | E5: Available h | F5: UF h | G5: UP h | H5: UR h | I5: Assigned h | J5: Release approved 1/0 | K5: Usable approved h | L5: Capacity breach h | M5: Unassigned h | N5: Release owner / evidence
A6: E01 | B6: Engineering | C6: 96 | D6: =Inputs!$B$18 | E6: =MAX(0,D6-C6) | F6: 0 | G6: 0 | H6: 0 | I6: =SUM(F6:H6) | J6: 0 | K6: =MIN(I6,E6)*J6 | L6: =MAX(0,I6-E6) | M6: =MAX(0,E6-I6) | N6: Not approved in case data; keep J=0 until named manager documents release and service cover.
A7: E02 | B7: Engineering | C7: 96 | D7: =Inputs!$B$18 | E7: =MAX(0,D7-C7) | F7: 0 | G7: 0 | H7: 0 | I7: =SUM(F7:H7) | J7: 0 | K7: =MIN(I7,E7)*J7 | L7: =MAX(0,I7-E7) | M7: =MAX(0,E7-I7) | N7: Not approved in case data; keep J=0 until named manager documents release and service cover.
A8: E03 | B8: Engineering | C8: 96 | D8: =Inputs!$B$18 | E8: =MAX(0,D8-C8) | F8: 0 | G8: 0 | H8: 0 | I8: =SUM(F8:H8) | J8: 0 | K8: =MIN(I8,E8)*J8 | L8: =MAX(0,I8-E8) | M8: =MAX(0,E8-I8) | N8: Not approved in case data; keep J=0 until named manager documents release and service cover.
A9: E04 | B9: Engineering | C9: 96 | D9: =Inputs!$B$18 | E9: =MAX(0,D9-C9) | F9: 0 | G9: 0 | H9: 0 | I9: =SUM(F9:H9) | J9: 0 | K9: =MIN(I9,E9)*J9 | L9: =MAX(0,I9-E9) | M9: =MAX(0,E9-I9) | N9: Not approved in case data; keep J=0 until named manager documents release and service cover.
A10: E05 | B10: Engineering | C10: 96 | D10: =Inputs!$B$18 | E10: =MAX(0,D10-C10) | F10: 0 | G10: 0 | H10: 0 | I10: =SUM(F10:H10) | J10: 0 | K10: =MIN(I10,E10)*J10 | L10: =MAX(0,I10-E10) | M10: =MAX(0,E10-I10) | N10: Not approved in case data; keep J=0 until named manager documents release and service cover.
A11: E06 | B11: Engineering | C11: 96 | D11: =Inputs!$B$18 | E11: =MAX(0,D11-C11) | F11: 0 | G11: 0 | H11: 0 | I11: =SUM(F11:H11) | J11: 0 | K11: =MIN(I11,E11)*J11 | L11: =MAX(0,I11-E11) | M11: =MAX(0,E11-I11) | N11: Not approved in case data; keep J=0 until named manager documents release and service cover.
A12: E07 | B12: Engineering | C12: 96 | D12: =Inputs!$B$18 | E12: =MAX(0,D12-C12) | F12: 0 | G12: 0 | H12: 0 | I12: =SUM(F12:H12) | J12: 0 | K12: =MIN(I12,E12)*J12 | L12: =MAX(0,I12-E12) | M12: =MAX(0,E12-I12) | N12: Not approved in case data; keep J=0 until named manager documents release and service cover.
A13: E08 | B13: Engineering | C13: 96 | D13: =Inputs!$B$18 | E13: =MAX(0,D13-C13) | F13: 0 | G13: 0 | H13: 0 | I13: =SUM(F13:H13) | J13: 0 | K13: =MIN(I13,E13)*J13 | L13: =MAX(0,I13-E13) | M13: =MAX(0,E13-I13) | N13: Not approved in case data; keep J=0 until named manager documents release and service cover.
A14: E09 | B14: Engineering | C14: 96 | D14: =Inputs!$B$18 | E14: =MAX(0,D14-C14) | F14: 0 | G14: 0 | H14: 0 | I14: =SUM(F14:H14) | J14: 0 | K14: =MIN(I14,E14)*J14 | L14: =MAX(0,I14-E14) | M14: =MAX(0,E14-I14) | N14: Not approved in case data; keep J=0 until named manager documents release and service cover.
A15: E10 | B15: Engineering | C15: 96 | D15: =Inputs!$B$18 | E15: =MAX(0,D15-C15) | F15: 0 | G15: 0 | H15: 0 | I15: =SUM(F15:H15) | J15: 0 | K15: =MIN(I15,E15)*J15 | L15: =MAX(0,I15-E15) | M15: =MAX(0,E15-I15) | N15: Not approved in case data; keep J=0 until named manager documents release and service cover.
A16: E11 | B16: Engineering | C16: 96 | D16: =Inputs!$B$18 | E16: =MAX(0,D16-C16) | F16: 0 | G16: 0 | H16: 0 | I16: =SUM(F16:H16) | J16: 0 | K16: =MIN(I16,E16)*J16 | L16: =MAX(0,I16-E16) | M16: =MAX(0,E16-I16) | N16: Not approved in case data; keep J=0 until named manager documents release and service cover.
A17: E12 | B17: Engineering | C17: 96 | D17: =Inputs!$B$18 | E17: =MAX(0,D17-C17) | F17: 0 | G17: 0 | H17: 0 | I17: =SUM(F17:H17) | J17: 0 | K17: =MIN(I17,E17)*J17 | L17: =MAX(0,I17-E17) | M17: =MAX(0,E17-I17) | N17: Not approved in case data; keep J=0 until named manager documents release and service cover.
... A65: E60 | B65: Legacy experts | C65: 112 | D65: =Inputs!$B$18 | E65: =MAX(0,D65-C65) | F65: 0 | G65: 0 | H65: 0 | I65: =SUM(F65:H65) | J65: 0 | K65: =MIN(I65,E65)*J65 | L65: =MAX(0,I65-E65) | M65: =MAX(0,E65-I65) | N65: Not approved in case data; keep J=0 until named manager documents release and service cover.

Sheet Four scenarios
A2: Four arrangements — conditional full-release comparison
A5: Arrangement | B5: Workflow | C5: Duplicate 1/0 | D5: Role | E5: Pilot demand h | F5: Full available h | G5: Internal used h | H5: Role gap h | I5: Vendor workers | J5: Vendor cost INR
A6: Retained + duplicate | B6: 1 | C6: 1 | D6: Engineering | E6: =Inputs!D26*Inputs!E26+IF(D6="Data preparation",240*C6,0)+IF(B6=1,Inputs!F26,Inputs!G26)+Inputs!$B$16 | F6: =Inputs!B26*MAX(0,Inputs!$B$18-Inputs!C26) | G6: =MIN(E6,F6) | H6: =MAX(0,E6-G6) | I6: =IF(Inputs!$B$20>0,ROUNDUP(H6/Inputs!$B$20,0),0) | J6: =I6*Inputs!$B$19*Inputs!H26
A7: Retained + duplicate | B7: 1 | C7: 1 | D7: Analytics | E7: =Inputs!D27*Inputs!E27+IF(D7="Data preparation",240*C7,0)+IF(B7=1,Inputs!F27,Inputs!G27)+Inputs!$B$16 | F7: =Inputs!B27*MAX(0,Inputs!$B$18-Inputs!C27) | G7: =MIN(E7,F7) | H7: =MAX(0,E7-G7) | I7: =IF(Inputs!$B$20>0,ROUNDUP(H7/Inputs!$B$20,0),0) | J7: =I7*Inputs!$B$19*Inputs!H27
A8: Retained + duplicate | B8: 1 | C8: 1 | D8: Operations | E8: =Inputs!D28*Inputs!E28+IF(D8="Data preparation",240*C8,0)+IF(B8=1,Inputs!F28,Inputs!G28)+Inputs!$B$16 | F8: =Inputs!B28*MAX(0,Inputs!$B$18-Inputs!C28) | G8: =MIN(E8,F8) | H8: =MAX(0,E8-G8) | I8: =IF(Inputs!$B$20>0,ROUNDUP(H8/Inputs!$B$20,0),0) | J8: =I8*Inputs!$B$19*Inputs!H28
A9: Retained + duplicate | B9: 1 | C9: 1 | D9: Data preparation | E9: =Inputs!D29*Inputs!E29+IF(D9="Data preparation",240*C9,0)+IF(B9=1,Inputs!F29,Inputs!G29)+Inputs!$B$16 | F9: =Inputs!B29*MAX(0,Inputs!$B$18-Inputs!C29) | G9: =MIN(E9,F9) | H9: =MAX(0,E9-G9) | I9: =IF(Inputs!$B$20>0,ROUNDUP(H9/Inputs!$B$20,0),0) | J9: =I9*Inputs!$B$19*Inputs!H29
A10: Retained + duplicate | B10: 1 | C10: 1 | D10: Quality assurance | E10: =Inputs!D30*Inputs!E30+IF(D10="Data preparation",240*C10,0)+IF(B10=1,Inputs!F30,Inputs!G30)+Inputs!$B$16 | F10: =Inputs!B30*MAX(0,Inputs!$B$18-Inputs!C30) | G10: =MIN(E10,F10) | H10: =MAX(0,E10-G10) | I10: =IF(Inputs!$B$20>0,ROUNDUP(H10/Inputs!$B$20,0),0) | J10: =I10*Inputs!$B$19*Inputs!H30
A11: Retained + duplicate | B11: 1 | C11: 1 | D11: Legacy experts | E11: =Inputs!D31*Inputs!E31+IF(D11="Data preparation",240*C11,0)+IF(B11=1,Inputs!F31,Inputs!G31)+Inputs!$B$16 | F11: =Inputs!B31*MAX(0,Inputs!$B$18-Inputs!C31) | G11: =MIN(E11,F11) | H11: =MAX(0,E11-G11) | I11: =IF(Inputs!$B$20>0,ROUNDUP(H11/Inputs!$B$20,0),0) | J11: =I11*Inputs!$B$19*Inputs!H31
A12: Retained + single output | B12: 1 | C12: 0 | D12: Engineering | E12: =Inputs!D26*Inputs!E26+IF(D12="Data preparation",240*C12,0)+IF(B12=1,Inputs!F26,Inputs!G26)+Inputs!$B$16 | F12: =Inputs!B26*MAX(0,Inputs!$B$18-Inputs!C26) | G12: =MIN(E12,F12) | H12: =MAX(0,E12-G12) | I12: =IF(Inputs!$B$20>0,ROUNDUP(H12/Inputs!$B$20,0),0) | J12: =I12*Inputs!$B$19*Inputs!H26
A13: Retained + single output | B13: 1 | C13: 0 | D13: Analytics | E13: =Inputs!D27*Inputs!E27+IF(D13="Data preparation",240*C13,0)+IF(B13=1,Inputs!F27,Inputs!G27)+Inputs!$B$16 | F13: =Inputs!B27*MAX(0,Inputs!$B$18-Inputs!C27) | G13: =MIN(E13,F13) | H13: =MAX(0,E13-G13) | I13: =IF(Inputs!$B$20>0,ROUNDUP(H13/Inputs!$B$20,0),0) | J13: =I13*Inputs!$B$19*Inputs!H27
A14: Retained + single output | B14: 1 | C14: 0 | D14: Operations | E14: =Inputs!D28*Inputs!E28+IF(D14="Data preparation",240*C14,0)+IF(B14=1,Inputs!F28,Inputs!G28)+Inputs!$B$16 | F14: =Inputs!B28*MAX(0,Inputs!$B$18-Inputs!C28) | G14: =MIN(E14,F14) | H14: =MAX(0,E14-G14) | I14: =IF(Inputs!$B$20>0,ROUNDUP(H14/Inputs!$B$20,0),0) | J14: =I14*Inputs!$B$19*Inputs!H28
A15: Retained + single output | B15: 1 | C15: 0 | D15: Data preparation | E15: =Inputs!D29*Inputs!E29+IF(D15="Data preparation",240*C15,0)+IF(B15=1,Inputs!F29,Inputs!G29)+Inputs!$B$16 | F15: =Inputs!B29*MAX(0,Inputs!$B$18-Inputs!C29) | G15: =MIN(E15,F15) | H15: =MAX(0,E15-G15) | I15: =IF(Inputs!$B$20>0,ROUNDUP(H15/Inputs!$B$20,0),0) | J15: =I15*Inputs!$B$19*Inputs!H29
A16: Retained + single output | B16: 1 | C16: 0 | D16: Quality assurance | E16: =Inputs!D30*Inputs!E30+IF(D16="Data preparation",240*C16,0)+IF(B16=1,Inputs!F30,Inputs!G30)+Inputs!$B$16 | F16: =Inputs!B30*MAX(0,Inputs!$B$18-Inputs!C30) | G16: =MIN(E16,F16) | H16: =MAX(0,E16-G16) | I16: =IF(Inputs!$B$20>0,ROUNDUP(H16/Inputs!$B$20,0),0) | J16: =I16*Inputs!$B$19*Inputs!H30
A17: Retained + single output | B17: 1 | C17: 0 | D17: Legacy experts | E17: =Inputs!D31*Inputs!E31+IF(D17="Data preparation",240*C17,0)+IF(B17=1,Inputs!F31,Inputs!G31)+Inputs!$B$16 | F17: =Inputs!B31*MAX(0,Inputs!$B$18-Inputs!C31) | G17: =MIN(E17,F17) | H17: =MAX(0,E17-G17) | I17: =IF(Inputs!$B$20>0,ROUNDUP(H17/Inputs!$B$20,0),0) | J17: =I17*Inputs!$B$19*Inputs!H31
A18: Bounded + duplicate | B18: 2 | C18: 1 | D18: Engineering | E18: =Inputs!D26*Inputs!E26+IF(D18="Data preparation",240*C18,0)+IF(B18=1,Inputs!F26,Inputs!G26)+Inputs!$B$16 | F18: =Inputs!B26*MAX(0,Inputs!$B$18-Inputs!C26) | G18: =MIN(E18,F18) | H18: =MAX(0,E18-G18) | I18: =IF(Inputs!$B$20>0,ROUNDUP(H18/Inputs!$B$20,0),0) | J18: =I18*Inputs!$B$19*Inputs!H26
A19: Bounded + duplicate | B19: 2 | C19: 1 | D19: Analytics | E19: =Inputs!D27*Inputs!E27+IF(D19="Data preparation",240*C19,0)+IF(B19=1,Inputs!F27,Inputs!G27)+Inputs!$B$16 | F19: =Inputs!B27*MAX(0,Inputs!$B$18-Inputs!C27) | G19: =MIN(E19,F19) | H19: =MAX(0,E19-G19) | I19: =IF(Inputs!$B$20>0,ROUNDUP(H19/Inputs!$B$20,0),0) | J19: =I19*Inputs!$B$19*Inputs!H27
A20: Bounded + duplicate | B20: 2 | C20: 1 | D20: Operations | E20: =Inputs!D28*Inputs!E28+IF(D20="Data preparation",240*C20,0)+IF(B20=1,Inputs!F28,Inputs!G28)+Inputs!$B$16 | F20: =Inputs!B28*MAX(0,Inputs!$B$18-Inputs!C28) | G20: =MIN(E20,F20) | H20: =MAX(0,E20-G20) | I20: =IF(Inputs!$B$20>0,ROUNDUP(H20/Inputs!$B$20,0),0) | J20: =I20*Inputs!$B$19*Inputs!H28
A21: Bounded + duplicate | B21: 2 | C21: 1 | D21: Data preparation | E21: =Inputs!D29*Inputs!E29+IF(D21="Data preparation",240*C21,0)+IF(B21=1,Inputs!F29,Inputs!G29)+Inputs!$B$16 | F21: =Inputs!B29*MAX(0,Inputs!$B$18-Inputs!C29) | G21: =MIN(E21,F21) | H21: =MAX(0,E21-G21) | I21: =IF(Inputs!$B$20>0,ROUNDUP(H21/Inputs!$B$20,0),0) | J21: =I21*Inputs!$B$19*Inputs!H29
A22: Bounded + duplicate | B22: 2 | C22: 1 | D22: Quality assurance | E22: =Inputs!D30*Inputs!E30+IF(D22="Data preparation",240*C22,0)+IF(B22=1,Inputs!F30,Inputs!G30)+Inputs!$B$16 | F22: =Inputs!B30*MAX(0,Inputs!$B$18-Inputs!C30) | G22: =MIN(E22,F22) | H22: =MAX(0,E22-G22) | I22: =IF(Inputs!$B$20>0,ROUNDUP(H22/Inputs!$B$20,0),0) | J22: =I22*Inputs!$B$19*Inputs!H30
A23: Bounded + duplicate | B23: 2 | C23: 1 | D23: Legacy experts | E23: =Inputs!D31*Inputs!E31+IF(D23="Data preparation",240*C23,0)+IF(B23=1,Inputs!F31,Inputs!G31)+Inputs!$B$16 | F23: =Inputs!B31*MAX(0,Inputs!$B$18-Inputs!C31) | G23: =MIN(E23,F23) | H23: =MAX(0,E23-G23) | I23: =IF(Inputs!$B$20>0,ROUNDUP(H23/Inputs!$B$20,0),0) | J23: =I23*Inputs!$B$19*Inputs!H31
A24: Bounded + single output | B24: 2 | C24: 0 | D24: Engineering | E24: =Inputs!D26*Inputs!E26+IF(D24="Data preparation",240*C24,0)+IF(B24=1,Inputs!F26,Inputs!G26)+Inputs!$B$16 | F24: =Inputs!B26*MAX(0,Inputs!$B$18-Inputs!C26) | G24: =MIN(E24,F24) | H24: =MAX(0,E24-G24) | I24: =IF(Inputs!$B$20>0,ROUNDUP(H24/Inputs!$B$20,0),0) | J24: =I24*Inputs!$B$19*Inputs!H26
A25: Bounded + single output | B25: 2 | C25: 0 | D25: Analytics | E25: =Inputs!D27*Inputs!E27+IF(D25="Data preparation",240*C25,0)+IF(B25=1,Inputs!F27,Inputs!G27)+Inputs!$B$16 | F25: =Inputs!B27*MAX(0,Inputs!$B$18-Inputs!C27) | G25: =MIN(E25,F25) | H25: =MAX(0,E25-G25) | I25: =IF(Inputs!$B$20>0,ROUNDUP(H25/Inputs!$B$20,0),0) | J25: =I25*Inputs!$B$19*Inputs!H27
A26: Bounded + single output | B26: 2 | C26: 0 | D26: Operations | E26: =Inputs!D28*Inputs!E28+IF(D26="Data preparation",240*C26,0)+IF(B26=1,Inputs!F28,Inputs!G28)+Inputs!$B$16 | F26: =Inputs!B28*MAX(0,Inputs!$B$18-Inputs!C28) | G26: =MIN(E26,F26) | H26: =MAX(0,E26-G26) | I26: =IF(Inputs!$B$20>0,ROUNDUP(H26/Inputs!$B$20,0),0) | J26: =I26*Inputs!$B$19*Inputs!H28
A27: Bounded + single output | B27: 2 | C27: 0 | D27: Data preparation | E27: =Inputs!D29*Inputs!E29+IF(D27="Data preparation",240*C27,0)+IF(B27=1,Inputs!F29,Inputs!G29)+Inputs!$B$16 | F27: =Inputs!B29*MAX(0,Inputs!$B$18-Inputs!C29) | G27: =MIN(E27,F27) | H27: =MAX(0,E27-G27) | I27: =IF(Inputs!$B$20>0,ROUNDUP(H27/Inputs!$B$20,0),0) | J27: =I27*Inputs!$B$19*Inputs!H29
A28: Bounded + single output | B28: 2 | C28: 0 | D28: Quality assurance | E28: =Inputs!D30*Inputs!E30+IF(D28="Data preparation",240*C28,0)+IF(B28=1,Inputs!F30,Inputs!G30)+Inputs!$B$16 | F28: =Inputs!B30*MAX(0,Inputs!$B$18-Inputs!C30) | G28: =MIN(E28,F28) | H28: =MAX(0,E28-G28) | I28: =IF(Inputs!$B$20>0,ROUNDUP(H28/Inputs!$B$20,0),0) | J28: =I28*Inputs!$B$19*Inputs!H30
A29: Bounded + single output | B29: 2 | C29: 0 | D29: Legacy experts | E29: =Inputs!D31*Inputs!E31+IF(D29="Data preparation",240*C29,0)+IF(B29=1,Inputs!F31,Inputs!G31)+Inputs!$B$16 | F29: =Inputs!B31*MAX(0,Inputs!$B$18-Inputs!C31) | G29: =MIN(E29,F29) | H29: =MAX(0,E29-G29) | I29: =IF(Inputs!$B$20>0,ROUNDUP(H29/Inputs!$B$20,0),0) | J29: =I29*Inputs!$B$19*Inputs!H31
A32: Arrangement | B32: Demand h | C32: Available h | D32: Skill gap h | E32: Vendor workers | F32: Vendor INR | G32: Total incremental INR | H32: Budget balance | I32: Worker balance | J32: Status
A33: =A6 | B33: =SUM(E6:E11) | C33: =SUM(F6:F11) | D33: =SUM(H6:H11) | E33: =SUM(I6:I11) | F33: =SUM(J6:J11) | G33: =F33+Inputs!$B$17 | H33: =Inputs!$B$10-G33 | I33: =Inputs!$B$11-E33 | J33: =IF(Inputs!$B$20=0,"No vendor capacity",IF(OR(H33<0,I33<0),"Over budget/limit","Conditional feasibility"))
A34: =A12 | B34: =SUM(E12:E17) | C34: =SUM(F12:F17) | D34: =SUM(H12:H17) | E34: =SUM(I12:I17) | F34: =SUM(J12:J17) | G34: =F34+Inputs!$B$17 | H34: =Inputs!$B$10-G34 | I34: =Inputs!$B$11-E34 | J34: =IF(Inputs!$B$20=0,"No vendor capacity",IF(OR(H34<0,I34<0),"Over budget/limit","Conditional feasibility"))
A35: =A18 | B35: =SUM(E18:E23) | C35: =SUM(F18:F23) | D35: =SUM(H18:H23) | E35: =SUM(I18:I23) | F35: =SUM(J18:J23) | G35: =F35+Inputs!$B$17 | H35: =Inputs!$B$10-G35 | I35: =Inputs!$B$11-E35 | J35: =IF(Inputs!$B$20=0,"No vendor capacity",IF(OR(H35<0,I35<0),"Over budget/limit","Conditional feasibility"))
A36: =A24 | B36: =SUM(E24:E29) | C36: =SUM(F24:F29) | D36: =SUM(H24:H29) | E36: =SUM(I24:I29) | F36: =SUM(J24:J29) | G36: =F36+Inputs!$B$17 | H36: =Inputs!$B$10-G36 | I36: =Inputs!$B$11-E36 | J36: =IF(Inputs!$B$20=0,"No vendor capacity",IF(OR(H36<0,I36<0),"Over budget/limit","Conditional feasibility"))
A39: Authority condition | B39: Bounded hours require decision thresholds, owners and clock; global pricing, consent and major architecture exceptions retain their owners. Q5.05; P008–P014.
A40: Duplication condition | B40: Exclude only when a single authoritative preparation output and receiving owner are established. Q5.04; P024.
A41: Release condition | B41: Internal used h assumes full release within role. Validate named employee allocations and service cover before recommending. Q5.03; P063; P183–P184.

Sheet Worked example
A2: Worked examples — emulate the method, not a prescribed answer
A5: Step | B5: Illustrative calculation / decision | C5: Result | D5: Evidence and concept
A6: 1 Productive time | B6: 4 × 40 × (1 − 20%) | C6: 128 | D6: Q5.02; allowance precedes fixed service deduction.
A7: 2 Individual available | B7: Data-preparation employee: 128 − 96 | C7: 32 | D7: Q5.03; headcount is not wholly deployable.
A8: 3 Retained demand | B8: Data preparation: 6 × 96 | C8: 576 | D8: Legacy work remains protected.
A9: 4 Baseline pilot | B9: 60 × 4 + duplicate 60 × 4 + 64 coordination | C9: 544 | D9: Q5.04–05; task demand differs from role staffing.
A10: 5 Full available supply | B10: 6 × 32 | C10: 192 | D10: Conditional on release; do not assume approval.
A11: 6 Skill-specific gap | B11: MAX(0, 544 − 192) | C11: 352 | D11: Sum role gaps, not net aggregate difference.
A12: 7 Gross FTE | B12: (576 + 544) /128 | C12: 8.75 | D12: Q5.08; rounded whole role positions = 9.
A13: 8 Vendor workers | B13: ROUNDUP(352/102.4,0) | C13: 4 | D13: Q5.07; vendor capacity discounted for proficiency.
A14: 9 Vendor cost | B14: 4 × 160 paid hours × ₹550 | C14: 352000 | D14: Paid hours, not effective hours, determine invoice.
A15: 10 Single output + bounded | B15: 240 task h + 32 coord h − 192 supply h | C15: 80 | D15: Conditional redesign gap; no assumed cross-skill transfer.
A16: 11 Vendor revised | B16: 1 vendor ×160 ×₹550 | C16: 88000 | D16: This is one role; test all roles against total budget.
A19: Problem | B19: A duplicated customer-pack output consumes scarce role-hours. P024. | C19: Solution cue | D19: Establish one authoritative preparation output and receiving owner before excluding repetition.
A20: Related concept | B20: Job analysis traces tasks; job design changes handoffs and accountability. | C20: AS2 link | D20: Deliverable 2 supplies numerical role need; Deliverable 1 supplies authority.
A21: Sample allocation | B21: E41: UP 24h + UR 8h =32h; legacy 96h retained. | C21: Release | D21: Flag remains 0 until documented approval. Sample is not pre-filled in student allocation.
A22: Student task | B22: Complete the other roles, test vendor budget and prepare at least three JD/JS rows. | C22: Defend | D22: Explain why alternative numbers or designs are justified.

Sheet Job design
A2: Job analysis and design — complete three roles
A5: Role | B5: Business output / P or Q ID | C5: Duties and hours | D5: JD: responsibility / reporting | E5: JD: authority and escalation | F5: JS: knowledge / skills | G5: JS: evidence / selection method | H5: Design choice and workload effect | I5: Onboarding / knowledge transfer | J5: Owner / ready date / assumptions | K5: AS2 link
A6: ILLUSTRATIVE: Customer-data preparation specialist | B6: Common customer pack; P024; P069; Q5.04 | C6: Prepare 60 packs × 4h and document exceptions; 32 coordination h under bounded scenario. Pool-level demand, not one employee’s assignment. | D6: Prepare, reconcile and validate shared output; proposed reporting to operating manager with pilot interface. | E6: Accountable for preparation quality within approved access; customer permission remains with authorized owner; escalate access or ambiguity. | F6: Data reconciliation, exception interpretation, documentation and confidentiality; proposed, not issued requirements. | G6: Anomalous customer-record work sample; structured questions; same scoring rubric and threshold for all. | H6: Single-output ownership removes 240 duplicate task hours only if receiver accepts output; requires redesigned handoff, not just extra headcount. | I6: Protected shadowing and tested exception handoff; estimate any extra effort once beyond Q5. | J6: Operating owner and receiving owner to be named; no release until access and service cover confirmed. | K6: D1 structure; D2 role gap; D3 selection/onboarding.
A7: ILLUSTRATIVE: Quality assurance specialist | B7: Validation of 80 tasks; P019–P020; Q5.04 | C7: Run 80 validation tasks × 3h = 240 task hours; 24 coordination h under bounded scenario; role-pool demand 264h. | D7: Report to QA/technical owner; maintain defect evidence, retests and acceptance record. | E7: Can validate against approved criteria and recommend readiness; cannot approve major architecture exceptions or customer permission; escalate threshold breaches. | F7: Test execution, evidence interpretation, defect triage, risk judgement and documentation; proposed requirements. | G7: Standardized validation exercise, defect log and structured exception questions. | H7: Enrichment is justified only when the role has defined acceptance criteria and a named escalation owner; does not transfer reserved approvals. | I7: Orientation to criteria and access, supervised validation, sample audit and documented readiness sign-off. | J7: QA/technical owner; criteria and thresholds must be confirmed before work starts. | K7: D1 authority boundaries; D2 workload; D3 selection and readiness gate.
A8: ILLUSTRATIVE: Legacy expert / knowledge-transfer specialist | B8: 40 documentation/teaching blocks × 4h = 160 task hours; P027; P069–P071; P168; Q5.04 | C8: Document legacy process and exceptions, coach receiving staff and test learning; 32 coordination h under bounded scenario; demand 192h. | D8: Source-service manager remains accountable for release; delivery manager protects teaching sequence and service cover. | E8: Can explain and document known exceptions; cannot unilaterally stop legacy service or grant customer access; escalate undocumented/high-risk cases. | F8: Tacit process knowledge, exception reasoning, clear teaching, documentation and service-risk awareness; proposed. | G8: Explain a complex exception, produce a runbook and teach a second person who completes a test case. | H8: Protected rotation/knowledge transfer, not an added full workload; existing service must be covered before release. | I8: Protected shadowing, teach-back, exception test and service-owner acceptance; additional hours must not be double-counted with Q5. | J8: Source-service owner to approve release; receiving owner to sign off competence; timing remains to be agreed. | K8: D1 service protection; D2 role demand; D3 readiness and onboarding.

Sheet Selection example
A2: Illustrative selection scorecard — Q6.05 assumptions
A5: Criterion | B5: Weight | C5: Candidate A /5 | D5: Candidate B /5 | E5: Evidence and fairness cue
A6: Work sample | B6: 0.4 | C6: 4 | D6: 3 | E6: Proposed weights/scores; verify genuine role relevance.
A7: Exception judgement | B7: 0.35 | C7: 3 | D7: 4 | E7: Do not substitute opportunity-dependent experience for demonstrated competence. P063.
A8: Documentation | B8: 0.25 | C8: 4 | D8: 3 | E8: Use same task, instructions and rubric. P069–P071.
A10: Weight total | B10: =SUM(B6:B8)
A11: Weighted /5 | C11: =SUMPRODUCT(B6:B8,C6:C8) | D11: =SUMPRODUCT(B6:B8,D6:D8)
B12: Illustrative ranking only: A = 3.65/5; B = 3.35/5. Do not appoint on total alone if an essential competency threshold is not met.
A13: Student action | B13: Use role-linked criteria, a common task, documented anchors and an agreed minimum threshold; replace these fictional examples if real evidence is available.
A14: P–J fit | B14: P–J fit: assess demonstrated ability to perform defined duties; separate trainable gaps from essential entry requirements.
A15: P–O fit | B15: P–O fit: explain job-relevant expectations and support; avoid identity, background or subjective similarity as a proxy.
A16: Onboarding gate | B16: Onboarding gate: confirm access, role authority, service cover, supervised practice and accepted output before marking ready-to-work.

Sheet Assumptions
A2: Assumptions, authority and decision record
A5: ID | B5: Missing detail / decision | C5: Baseline / proposed assumption | D5: Source P/Q ID | E5: Why reasonable | F5: Owner / verification | G5: Downside test | H5: Affected cell / AS2 decision
A6: Q6.01 | B6: Role accountabilities / competencies | C6: Student-developed JD/JS; no fictitious recovered records. | D6: P061–P064; P069–P071 | E6: Explain task relevance. | F6: Business owner + HR | G6: Authority not granted | H6: Job design; D1–D3
A7: Q6.02 | B7: Extra onboarding / specialist effort | C7: Default 0 only if Q5 tasks/allowance already cover it; otherwise estimate hours once. | D7: Q5.06; P168 | E7: Avoid double-counting teaching blocks. | F7: Name learner/supervisor and cover owner | G7: Additional effort consumes capacity | H7: Inputs B16; per-role override may be required
A8: Q6.03 | B8: Vendor delayed start / lower proficiency | C8: Baseline delay0 / proficiency0.8; downside examples delay1 or proficiency0.6 are student scenarios. | D8: Q5.07 | E8: Record which assumption is changed. | F8: Procurement | G8: Less effective capacity | H8: Inputs B15 / B9
A9: Q6.04 | B9: Additional cash outlay | C9: Baseline extra cost0; recruitment/induction cash outside vendor rates is a labelled estimate. | D9: P187–P190; P208 | E9: No salary or revenue record supplied. | F9: Finance | G9: Higher transition cash need | H9: Inputs B17
A10: Q6.05 | B10: Selection criteria / weights / scores | C10: Illustrative 40/35/25; fictitious candidate scores. Replace and justify. | D10: P063; R3/R4 | E10: Role-specific evidence only. | F10: HR + line manager | G10: Threshold excludes capable internal candidate | H10: Selection example
A11: Q6.06 | B11: Release and duplication permissions | C11: Default release flags0; duplicate included. Identify evidence before changing. | D11: P024; P027; P183–P184 | E11: Time available is not authorized deployment. | F11: Named operating and receiving owners | G11: Approval refused | H11: Employee allocations J; Inputs B14
A12: Q6.07 | B12: Weekly demand timing | C12: Q5 provides four-week totals; equal weekly phasing is not issued evidence. | D12: P019–P021; P189 | E12: If proposing delayed supply, state work sequence. | F12: Delivery owner | G12: Deadline precedes vendor readiness | H12: Four scenarios and recommendation
A13: Q5-S1 | B13: Bounded delegation | C13: Scenario 4 uses bounded coordination hours only if documented thresholds, named decision owners and response clocks are accepted. | D13: Q5.05; P008–P014; P028 | E13: Tests a feasible option without assuming all authority moves. | F13: Global/regional technical and commercial owners | G13: If not accepted, use retained-approval scenarios. | H13: Inputs B13; Four scenarios rows 24–29
A14: Q5-S2 | B14: Single customer-data output | C14: Remove 240 duplicate task hours only after one authoritative output and receiver are agreed. | D14: Q5.04; P024 | E14: Prevents hiring against duplicate work without proving both outputs are needed. | F14: Product + regional operations receiving owners | G14: If receiver refuses, set duplicate flag to 1. | H14: Inputs B14; Four scenarios C24:C29
A15: Q5-S3 | B15: Full internal release | C15: Potential supply assumes full release of role-pool capacity; individual allocation sheet remains at zero approved hours until evidence exists. | D15: Q5.03; P027; P183–P184 | E15: Protects existing services and prevents theoretical capacity being treated as approved deployment. | F15: Named line/source-service managers | G15: If fewer hours are approved, recalculate with actual employee flags/hours. | H15: Employee allocations J/K; Work and gaps H/J
A16: Q5-S4 | B16: Vendor proficiency sensitivity | C16: Base 80%; downside 60% are scenario values, not measured Meridian performance. | D16: Q5.07; Q6.03 | E16: Tests whether vendor budget and coverage remain workable under lower ramp-up. | F16: Procurement + role owner | G16: 60% lowers effective capacity per vendor from 102.4h to 76.8h. | H16: Inputs B9/B20; Four scenarios vendor calculations

Sheet Case extracts
A2: Case paragraph extracts — original IDs retained
A5: Case paragraph ID | B5: Original narrative extract
A6: P008 | B6: P008 At 7:42 on a Monday morning, Ananya Rao, the country leader responsible for Meridian Global Capability Center India, receives two attachments bearing the same board meeting date. One describes the India centre as the future owner of two global platforms, selected enterprise processes and AI-enabled decision products. The other reserves decisions about customer access, pricing, architecture and exceptions for executives elsewhere. Rao does not know whether the second attachment was circulated by mistake or was intended to qualify the first. The distinction has practical consequences. Accountability for a product outcome means India will be asked to explain whether the product meets its purpose. A right to recommend means India can prepare a proposal but must wait for someone else to authorize important parts of it. Those arrangements can coexist, but only if their boundaries and dependencies are workable. The documents do not yet explain how India can deliver the promised outcome when a necessary decision is delayed or refused elsewhere. Rao circles the language of ownership and recommendation. Beside the two passages she writes, “When India must answer for the outcome, who must answer for a decision India is not allowed to make?” She leaves both attachments in the board pack. The unresolved wording could determine what the proposed jobs will actually allow people to do. For Rao, the contradiction would surface in an ordinary review of a product team’s performance. The team could be asked why a customer problem remained unresolved, yet its explanation might depend on a decision that only a regional office could make. The first attachment would support the demand for an answer from India; the second would support the region’s insistence that India should have waited. Neither attachment described how to handle that disagreement. Rao’s difficulty was therefore not a lack of ambition for the centre. She needed to know whether the board was changing the work, the authority to perform it, or only the location at which an unsatisfactory outcome would be reported.
A7: P009 | B7: P009 Meridian Global Capability Center India, referred to as MGCCI, employs 8,400 people. It began twenty-two years earlier with finance processing and application support and grew into engineering, data, cybersecurity, procurement, people services and customer operations. Its reputation was earned by performing work accurately and reliably across time zones. That existing work is not a disposable past: customers and internal business units still depend on it. The parent now wants shorter product cycles, greater resilience and more original design from India. These ambitions must be pursued while current services continue, within a restricted first-year budget for a three-year transition. Rao therefore faces a transition problem as well as a future-design problem. People cannot be counted as wholly available for a new mandate while their old duties remain unchanged. Nor can promised savings be treated as available cash before the work producing the cost has safely stopped. The centre must identify what will change, what must continue and how the two will be supported during the overlap.
A8: P010 | B8: P010 Meridian’s public account of the GCC emphasizes integrated global capability: specialist talent in India should help shape consequential work across markets. Its operating procedures still send many important decisions back to headquarters or regional offices. An advisory team arrives before the organization has settled which description governs an actual customer request. “Before you show me a new organization chart, follow one customer request,” Rao tells the advisers. “Show me what the team can decide, what it must send elsewhere and where the answer stops.” Their immediate question is concrete. When the centre promises a product outcome, which people can authorize the steps needed to achieve it, what evidence must they see and what happens when their decisions depend on one another? A reporting line can identify a manager without answering those questions. A delivery date can identify a target without confirming that the necessary permissions will exist in time. The release now approaching its deadline will expose the difference. To understand it, the story first returns to the demonstration held in the week before Rao received the two attachments. MOVEMENT I | THE RELEASE THAT DID NOT BELONG TO ANYONE The board’s clock
A9: P019 | B9: P019 The project plan said the feature was ready on Monday. The system log showed a failed validation on Tuesday. Customer operations said the needed consent was never in place, and the engineering team said it had been told that consent was routine. Each timestamp was accurate for a different stage. The disagreement began when managers treated all three as one release date. An engineer using the project plan could reasonably report that a piece of development work was complete. The failed validation meant that readiness for the proposed use still needed examination. Customer operations was answering a further question: whether the actual use had been permitted. Treating any one of these statements as a lie would obscure the work still outstanding. The consequential error was to let the word “ready” move from one record to another without carrying the condition attached to it. A customer hearing the same word would not know that Meridian’s functions were referring to different stopping points.
A10: P020 | B10: P020 A junior analyst assembled a timeline with three clocks: when technical work could proceed, when a commercial decision could be made, and when customer use would be permitted. The clocks never ran together. An approval timestamp appeared in the system after the architecture council had already deferred its exception, though an email said the commercial lead had verbally accepted the price earlier. The analyst could not determine whether that verbal assent counted. Nobody wanted to sign a revised record that might make their area look responsible for the delay. The three clocks describe different kinds of readiness, not three alternative stories from which a convenient one can be selected. Technical readiness concerns the feature and its evidence; commercial readiness concerns the terms and commitments; permission for customer use concerns the actual configuration and data. An earlier timestamp on one clock cannot establish that the others were complete. The timeline must show both the separate stages and the point at which they can legitimately be brought together.
A11: P021 | B11: P021 The board report reduced the sequence to “late escalation by India.” Kabir produced his six-week-old message. Elena said early notice was not equivalent to a complete decision pack. Kabir agreed that the pack had gaps; he asked why no one had named them until the deadline. Devika pointed to an overlooked data quality warning. Each challenge made the preceding explanation less complete without making it false. The report had used the date of the formal escalation, not the date of Kabir’s first warning. Both dates were accurate within their respective records. One made the delay seem like a local failure; the other showed a decision waiting for several functions. Rao asked for the missing correspondence before anyone settled the account in the board minutes. The board secretary asked Kabir to sign off the phrase “late escalation.” He refused to certify it without his earlier message attached. Elena agreed to attach the message but wanted the gaps in the pack noted as well. The compromise produced a report with two explanations beside the same missed date. A director looking only at the headline would see tardiness in Bengaluru; one reading the attachment would see a warning that had crossed several offices without becoming a decision. Neither record alone would tell the board whether the next release could be authorized safely. Kabir’s six-week-old message mattered because it contradicted the suggestion that the dependency had become visible only at the last moment. Elena’s objection mattered because a warning could arrive before the material needed for a decision. Devika’s data warning mattered because neither chronology settled whether the release itself was sound. A fair account had to retain all three rather than use one to cancel the others. It also had to ask what happened after the first warning: whether anyone identified the missing material, who was expected to supply it and why that exchange did not lead to a decision. The headline was consequential because it could turn a cross-functional failure into a recorded deficiency of the India team while leaving the next release exposed to the same arrangement.
